<?xml version="1.0"?>
<robot name="link_calibration" xmlns:xacro="http://www.ros.org/wiki/xacro">

  <xacro:macro name="inertial_link"
               params="name">
    <link name="${name}">
      <inertial>
        <origin xyz="0 0 1" rpy="0 0 0" />
        <mass value="0.01" />
        <inertia ixx="1.0" ixy="0.0" ixz="0.0"
                 iyy="1.0" iyz="0.0"
                 izz="1.0" />
      </inertial>
    </link>
  </xacro:macro>

  <xacro:macro name="prismatic_calibration_joint"
               params="name parent axis">
    <joint name="${name}_joint" type="prismatic">
      <parent link="${parent}" />
      <child link="${name}" />
      <axis xyz="${axis}" />
      <limit lower="-0.5" upper="+0.5" effort="999" velocity="999" />
    </joint>
  </xacro:macro>

  <xacro:macro name="revolute_calibration_joint"
               params="name parent axis">
    <joint name="${name}_joint" type="revolute">
      <parent link="${parent}" />
      <child link="${name}" />
      <axis xyz="${axis}" />
      <limit lower="-0.5" upper="+0.5" effort="999" velocity="999" />
    </joint>
  </xacro:macro>

  <!-- NOTE! Must have a mass/inertial so that Gazebo does not ignore these... -->
  <xacro:macro name="fixed_link"
               params="name parent translateX:=0 translateY:=0 translateZ:=0 rotX:=0.0 rotY:=0.0 rotZ:=0.0">
    <inertial_link name="${name}" />

    <gazebo reference="${name}">
      <turnGravityOff>true</turnGravityOff>
      <material>Gazebo/Orange</material>
    </gazebo>

    <!-- Base offset -->
    <joint name="${name}_joint" type="fixed">
      <parent link="${parent}" />
      <child link="${name}" />
      <origin xyz="${translateX} ${translateY} ${translateZ}" rpy="${rotX} ${rotY} ${rotZ}" />
    </joint>
  </xacro:macro>

  <!-- NOTE! Must have a mass/inertial so that Gazebo does not ignore these... -->
  <xacro:macro name="link_calibration"
               params="name parent translateX:=0.0 translateY:=0.0 translateZ:=0.0 rotX:=0.0 rotY:=0.0 rotZ:=0.0">
    <inertial_link name="${name}_base" />
    <inertial_link name="${name}_x_offset" />
    <inertial_link name="${name}_y_offset" />
    <inertial_link name="${name}_z_offset" />
    <inertial_link name="${name}_pitch" />
    <inertial_link name="${name}_roll" />
    <inertial_link name="${name}_yaw" />
    <inertial_link name="${name}" />

    <gazebo reference="${name}">
      <turnGravityOff>true</turnGravityOff>
      <material>Gazebo/Orange</material>
    </gazebo>

    <!-- Base offset -->
    <joint name="${name}_joint" type="fixed">
      <parent link="${parent}" />
      <child link="${name}_base" />
      <origin xyz="${translateX} ${translateY} ${translateZ}" rpy="${rotX} ${rotY} ${rotZ}" />
    </joint>

    <prismatic_calibration_joint name="${name}_x_offset"
                                 parent="${name}_base"
                                 axis="1 0 0" />
    <prismatic_calibration_joint name="${name}_y_offset"
                                 parent="${name}_x_offset"
                                 axis="0 1 0" />
    <prismatic_calibration_joint name="${name}_z_offset"
                                 parent="${name}_y_offset"
                                 axis="0 0 1" />
    <revolute_calibration_joint name="${name}_pitch"
                                parent="${name}_z_offset"
                                axis="0 1 0" />
    <revolute_calibration_joint name="${name}_roll"
                                parent="${name}_pitch"
                                axis="1 0 0" />
    <revolute_calibration_joint name="${name}_yaw"
                                parent="${name}_roll"
                                axis="0 0 1" />
    <joint name="${name}_final_joint" type="fixed">
      <parent link="${name}_yaw" />
      <child link="${name}" />
    </joint>
  </xacro:macro>
</robot>
